 * Running on http://127.0.0.1:5000/
 * Restarting with reloader
 * Detected change in 'unome.py', reloading
 * Restarting with reloader
 * Detected change in 'unome.py', reloading
 * Restarting with reloader
 * Detected change in 'unome.py', reloading
 * Restarting with reloader
 * Detected change in 'unome.py', reloading
 * Restarting with reloader
Traceback (most recent call last):
  File "unome.py", line 28, in <module>
    @app.route('twitter_login')
  File "/Library/Python/2.7/site-packages/flask/app.py", line 977, in decorator
    self.add_url_rule(rule, endpoint, f, **options)
  File "/Library/Python/2.7/site-packages/flask/app.py", line 63, in wrapper_func
    return f(self, *args, **kwargs)
  File "/Library/Python/2.7/site-packages/flask/app.py", line 943, in add_url_rule
    rule = self.url_rule_class(rule, methods=methods, **options)
  File "/Library/Python/2.7/site-packages/werkzeug/routing.py", line 550, in __init__
    raise ValueError('urls must start with a leading slash')
ValueError: urls must start with a leading slash
 * Running on http://0.0.0.0:2074/
Traceback (most recent call last):
  File "unome.py", line 52, in <module>
    app.run(debug=True, host='0.0.0.0', port=2074)
  File "/usr/local/lib/python2.7/dist-packages/flask/app.py", line 739, in run
    run_simple(host, port, self, **options)
  File "/usr/local/lib/python2.7/dist-packages/werkzeug/serving.py", line 613, in run_simple
    test_socket.bind((hostname, port))
  File "/usr/lib/python2.7/socket.py", line 224, in meth
    return getattr(self._sock,name)(*args)
socket.error: [Errno 98] Address already in use
 * Running on http://0.0.0.0:2074/
Traceback (most recent call last):
  File "unome.py", line 52, in <module>
    app.run(debug=True, host='0.0.0.0', port=2074)
  File "/usr/local/lib/python2.7/dist-packages/flask/app.py", line 739, in run
    run_simple(host, port, self, **options)
  File "/usr/local/lib/python2.7/dist-packages/werkzeug/serving.py", line 613, in run_simple
    test_socket.bind((hostname, port))
  File "/usr/lib/python2.7/socket.py", line 224, in meth
    return getattr(self._sock,name)(*args)
socket.error: [Errno 98] Address already in use
 * Running on http://0.0.0.0:2074/
Traceback (most recent call last):
  File "unome.py", line 52, in <module>
    app.run(debug=True, host='0.0.0.0', port=2074)
  File "/usr/local/lib/python2.7/dist-packages/flask/app.py", line 739, in run
    run_simple(host, port, self, **options)
  File "/usr/local/lib/python2.7/dist-packages/werkzeug/serving.py", line 613, in run_simple
    test_socket.bind((hostname, port))
  File "/usr/lib/python2.7/socket.py", line 224, in meth
    return getattr(self._sock,name)(*args)
socket.error: [Errno 98] Address already in use
 * Running on http://0.0.0.0:2074/
 * Restarting with reloader
 * Detected change in 'unome.py', reloading
 * Restarting with reloader
 * Detected change in 'unome.py', reloading
Unhandled exception in thread started by 
sys.excepthook is missing
lost sys.stderr
 * Restarting with reloader
 * Detected change in 'unome.py', reloading
 * Restarting with reloader
222.109.97.77 - - [13/Oct/2012 18:30:27] "GET /twitter_login HTTP/1.1" 500 -
Traceback (most recent call last):
  File "/usr/local/lib/python2.7/dist-packages/flask/app.py", line 1701, in __call__
    return self.wsgi_app(environ, start_response)
  File "/usr/local/lib/python2.7/dist-packages/flask/app.py", line 1689, in wsgi_app
    response = self.make_response(self.handle_exception(e))
  File "/usr/local/lib/python2.7/dist-packages/flask/app.py", line 1687, in wsgi_app
    response = self.full_dispatch_request()
  File "/usr/local/lib/python2.7/dist-packages/flask/app.py", line 1360, in full_dispatch_request
    rv = self.handle_user_exception(e)
  File "/usr/local/lib/python2.7/dist-packages/flask/app.py", line 1358, in full_dispatch_request
    rv = self.dispatch_request()
  File "/usr/local/lib/python2.7/dist-packages/flask/app.py", line 1344, in dispatch_request
    return self.view_functions[rule.endpoint](**req.view_args)
  File "/home/luman/project/Unome/unome.py", line 29, in login
    return twitter.authorize(callback=url_for('oauth_authorized', next=request.args.get('next') or request.referrer or None))
  File "/usr/local/lib/python2.7/dist-packages/flask_oauth.py", line 331, in authorize
    token = self.generate_request_token(callback)[0]
  File "/usr/local/lib/python2.7/dist-packages/flask_oauth.py", line 299, in generate_request_token
    type='token_generation_failed')
OAuthException: Failed to generate request token
222.109.97.77 - - [13/Oct/2012 18:30:28] "GET /twitter_login?__debugger__=yes&cmd=resource&f=style.css HTTP/1.1" 200 -
222.109.97.77 - - [13/Oct/2012 18:30:28] "GET /twitter_login?__debugger__=yes&cmd=resource&f=jquery.js HTTP/1.1" 200 -
Traceback (most recent call last):
  File "/usr/lib/python2.7/SocketServer.py", line 284, in _handle_request_noblock
    self.process_request(request, client_address)
  File "/usr/lib/python2.7/SocketServer.py", line 310, in process_request
    self.finish_request(request, client_address)
  File "/usr/lib/python2.7/SocketServer.py", line 323, in finish_request
    self.RequestHandlerClass(request, client_address, self)
  File "/usr/lib/python2.7/SocketServer.py", line 641, in __init__
    self.finish()
  File "/usr/lib/python2.7/SocketServer.py", line 694, in finish
    self.wfile.flush()
  File "/usr/lib/python2.7/socket.py", line 303, in flush
    self._sock.sendall(view[write_offset:write_offset+buffer_size])
error: [Errno 32] Broken pipe
222.109.97.77 - - [13/Oct/2012 18:30:28] "GET /twitter_login?__debugger__=yes&cmd=resource&f=debugger.js HTTP/1.1" 200 -
222.109.97.77 - - [13/Oct/2012 18:30:28] "GET /twitter_login HTTP/1.1" 500 -
Traceback (most recent call last):
  File "/usr/local/lib/python2.7/dist-packages/flask/app.py", line 1701, in __call__
    return self.wsgi_app(environ, start_response)
  File "/usr/local/lib/python2.7/dist-packages/flask/app.py", line 1689, in wsgi_app
    response = self.make_response(self.handle_exception(e))
  File "/usr/local/lib/python2.7/dist-packages/flask/app.py", line 1687, in wsgi_app
    response = self.full_dispatch_request()
  File "/usr/local/lib/python2.7/dist-packages/flask/app.py", line 1360, in full_dispatch_request
    rv = self.handle_user_exception(e)
  File "/usr/local/lib/python2.7/dist-packages/flask/app.py", line 1358, in full_dispatch_request
    rv = self.dispatch_request()
  File "/usr/local/lib/python2.7/dist-packages/flask/app.py", line 1344, in dispatch_request
    return self.view_functions[rule.endpoint](**req.view_args)
  File "/home/luman/project/Unome/unome.py", line 29, in login
    return twitter.authorize(callback=url_for('oauth_authorized', next=request.args.get('next') or request.referrer or None))
  File "/usr/local/lib/python2.7/dist-packages/flask_oauth.py", line 331, in authorize
    token = self.generate_request_token(callback)[0]
  File "/usr/local/lib/python2.7/dist-packages/flask_oauth.py", line 299, in generate_request_token
    type='token_generation_failed')
OAuthException: Failed to generate request token
222.109.97.77 - - [13/Oct/2012 18:30:28] "GET /favicon.ico HTTP/1.1" 404 -
222.109.97.77 - - [13/Oct/2012 18:30:28] "GET /twitter_login?__debugger__=yes&cmd=resource&f=style.css HTTP/1.1" 200 -
222.109.97.77 - - [13/Oct/2012 18:30:28] "GET /twitter_login?__debugger__=yes&cmd=resource&f=jquery.js HTTP/1.1" 200 -
222.109.97.77 - - [13/Oct/2012 18:30:28] "GET /twitter_login?__debugger__=yes&cmd=resource&f=debugger.js HTTP/1.1" 200 -
222.109.97.77 - - [13/Oct/2012 18:30:28] "GET /twitter_login?__debugger__=yes&cmd=resource&f=ubuntu.ttf HTTP/1.1" 200 -
222.109.97.77 - - [13/Oct/2012 18:30:28] "GET /twitter_login?__debugger__=yes&cmd=resource&f=source.png HTTP/1.1" 200 -
222.109.97.77 - - [13/Oct/2012 18:30:28] "GET /twitter_login?__debugger__=yes&cmd=resource&f=console.png HTTP/1.1" 200 -
222.109.97.77 - - [13/Oct/2012 18:30:28] "GET /favicon.ico HTTP/1.1" 404 -
222.109.97.77 - - [13/Oct/2012 18:30:33] "GET / HTTP/1.1" 200 -
222.109.97.77 - - [13/Oct/2012 18:30:33] "GET /favicon.ico HTTP/1.1" 404 -
222.109.97.77 - - [13/Oct/2012 18:30:35] "GET /twitter_login HTTP/1.1" 500 -
Traceback (most recent call last):
  File "/usr/local/lib/python2.7/dist-packages/flask/app.py", line 1701, in __call__
    return self.wsgi_app(environ, start_response)
  File "/usr/local/lib/python2.7/dist-packages/flask/app.py", line 1689, in wsgi_app
    response = self.make_response(self.handle_exception(e))
  File "/usr/local/lib/python2.7/dist-packages/flask/app.py", line 1687, in wsgi_app
    response = self.full_dispatch_request()
  File "/usr/local/lib/python2.7/dist-packages/flask/app.py", line 1360, in full_dispatch_request
    rv = self.handle_user_exception(e)
  File "/usr/local/lib/python2.7/dist-packages/flask/app.py", line 1358, in full_dispatch_request
    rv = self.dispatch_request()
  File "/usr/local/lib/python2.7/dist-packages/flask/app.py", line 1344, in dispatch_request
    return self.view_functions[rule.endpoint](**req.view_args)
  File "/home/luman/project/Unome/unome.py", line 29, in login
    return twitter.authorize(callback=url_for('oauth_authorized', next=request.args.get('next') or request.referrer or None))
  File "/usr/local/lib/python2.7/dist-packages/flask_oauth.py", line 331, in authorize
    token = self.generate_request_token(callback)[0]
  File "/usr/local/lib/python2.7/dist-packages/flask_oauth.py", line 299, in generate_request_token
    type='token_generation_failed')
OAuthException: Failed to generate request token
222.109.97.77 - - [13/Oct/2012 18:30:35] "GET /twitter_login?__debugger__=yes&cmd=resource&f=style.css HTTP/1.1" 200 -
222.109.97.77 - - [13/Oct/2012 18:30:35] "GET /twitter_login?__debugger__=yes&cmd=resource&f=jquery.js HTTP/1.1" 200 -
222.109.97.77 - - [13/Oct/2012 18:30:35] "GET /twitter_login?__debugger__=yes&cmd=resource&f=debugger.js HTTP/1.1" 200 -
222.109.97.77 - - [13/Oct/2012 18:30:35] "GET /twitter_login?__debugger__=yes&cmd=resource&f=ubuntu.ttf HTTP/1.1" 200 -
222.109.97.77 - - [13/Oct/2012 18:30:36] "GET /twitter_login?__debugger__=yes&cmd=resource&f=console.png HTTP/1.1" 200 -
222.109.97.77 - - [13/Oct/2012 18:30:36] "GET /twitter_login?__debugger__=yes&cmd=resource&f=source.png HTTP/1.1" 200 -
222.109.97.77 - - [13/Oct/2012 18:30:36] "GET /favicon.ico HTTP/1.1" 404 -
222.109.97.77 - - [13/Oct/2012 18:31:55] "GET /twitter_login HTTP/1.1" 500 -
Traceback (most recent call last):
  File "/usr/local/lib/python2.7/dist-packages/flask/app.py", line 1701, in __call__
    return self.wsgi_app(environ, start_response)
  File "/usr/local/lib/python2.7/dist-packages/flask/app.py", line 1689, in wsgi_app
    response = self.make_response(self.handle_exception(e))
  File "/usr/local/lib/python2.7/dist-packages/flask/app.py", line 1687, in wsgi_app
    response = self.full_dispatch_request()
  File "/usr/local/lib/python2.7/dist-packages/flask/app.py", line 1360, in full_dispatch_request
    rv = self.handle_user_exception(e)
  File "/usr/local/lib/python2.7/dist-packages/flask/app.py", line 1358, in full_dispatch_request
    rv = self.dispatch_request()
  File "/usr/local/lib/python2.7/dist-packages/flask/app.py", line 1344, in dispatch_request
    return self.view_functions[rule.endpoint](**req.view_args)
  File "/home/luman/project/Unome/unome.py", line 29, in login
    return twitter.authorize(callback=url_for('oauth_authorized', next=request.args.get('next') or request.referrer or None))
  File "/usr/local/lib/python2.7/dist-packages/flask_oauth.py", line 331, in authorize
    token = self.generate_request_token(callback)[0]
  File "/usr/local/lib/python2.7/dist-packages/flask_oauth.py", line 305, in generate_request_token
    session[self.name + '_oauthtok'] = tup
  File "/usr/local/lib/python2.7/dist-packages/werkzeug/local.py", line 339, in __setitem__
    self._get_current_object()[key] = value
  File "/usr/local/lib/python2.7/dist-packages/flask/sessions.py", line 57, in _fail
    raise RuntimeError('the session is unavailable because no secret '
RuntimeError: the session is unavailable because no secret key was set.  Set the secret_key on the application to something unique and secret.
222.109.97.77 - - [13/Oct/2012 18:31:55] "GET /twitter_login?__debugger__=yes&cmd=resource&f=style.css HTTP/1.1" 200 -
222.109.97.77 - - [13/Oct/2012 18:31:55] "GET /twitter_login?__debugger__=yes&cmd=resource&f=debugger.js HTTP/1.1" 200 -
222.109.97.77 - - [13/Oct/2012 18:31:55] "GET /twitter_login?__debugger__=yes&cmd=resource&f=jquery.js HTTP/1.1" 200 -
222.109.97.77 - - [13/Oct/2012 18:31:55] "GET /twitter_login?__debugger__=yes&cmd=resource&f=ubuntu.ttf HTTP/1.1" 200 -
222.109.97.77 - - [13/Oct/2012 18:31:55] "GET /twitter_login?__debugger__=yes&cmd=resource&f=source.png HTTP/1.1" 200 -
222.109.97.77 - - [13/Oct/2012 18:31:55] "GET /twitter_login?__debugger__=yes&cmd=resource&f=console.png HTTP/1.1" 200 -
222.109.97.77 - - [13/Oct/2012 18:31:55] "GET /favicon.ico HTTP/1.1" 404 -
222.109.97.77 - - [13/Oct/2012 18:31:58] "GET /twitter_login HTTP/1.1" 500 -
Traceback (most recent call last):
  File "/usr/local/lib/python2.7/dist-packages/flask/app.py", line 1701, in __call__
    return self.wsgi_app(environ, start_response)
  File "/usr/local/lib/python2.7/dist-packages/flask/app.py", line 1689, in wsgi_app
    response = self.make_response(self.handle_exception(e))
  File "/usr/local/lib/python2.7/dist-packages/flask/app.py", line 1687, in wsgi_app
    response = self.full_dispatch_request()
  File "/usr/local/lib/python2.7/dist-packages/flask/app.py", line 1360, in full_dispatch_request
    rv = self.handle_user_exception(e)
  File "/usr/local/lib/python2.7/dist-packages/flask/app.py", line 1358, in full_dispatch_request
    rv = self.dispatch_request()
  File "/usr/local/lib/python2.7/dist-packages/flask/app.py", line 1344, in dispatch_request
    return self.view_functions[rule.endpoint](**req.view_args)
  File "/home/luman/project/Unome/unome.py", line 29, in login
    return twitter.authorize(callback=url_for('oauth_authorized', next=request.args.get('next') or request.referrer or None))
  File "/usr/local/lib/python2.7/dist-packages/flask_oauth.py", line 331, in authorize
    token = self.generate_request_token(callback)[0]
  File "/usr/local/lib/python2.7/dist-packages/flask_oauth.py", line 305, in generate_request_token
    session[self.name + '_oauthtok'] = tup
  File "/usr/local/lib/python2.7/dist-packages/werkzeug/local.py", line 339, in __setitem__
    self._get_current_object()[key] = value
  File "/usr/local/lib/python2.7/dist-packages/flask/sessions.py", line 57, in _fail
    raise RuntimeError('the session is unavailable because no secret '
RuntimeError: the session is unavailable because no secret key was set.  Set the secret_key on the application to something unique and secret.
222.109.97.77 - - [13/Oct/2012 18:31:58] "GET /twitter_login?__debugger__=yes&cmd=resource&f=style.css HTTP/1.1" 200 -
222.109.97.77 - - [13/Oct/2012 18:31:58] "GET /twitter_login?__debugger__=yes&cmd=resource&f=jquery.js HTTP/1.1" 200 -
222.109.97.77 - - [13/Oct/2012 18:31:58] "GET /twitter_login?__debugger__=yes&cmd=resource&f=debugger.js HTTP/1.1" 200 -
222.109.97.77 - - [13/Oct/2012 18:31:58] "GET /twitter_login?__debugger__=yes&cmd=resource&f=ubuntu.ttf HTTP/1.1" 200 -
222.109.97.77 - - [13/Oct/2012 18:31:58] "GET /twitter_login?__debugger__=yes&cmd=resource&f=console.png HTTP/1.1" 200 -
222.109.97.77 - - [13/Oct/2012 18:31:58] "GET /twitter_login?__debugger__=yes&cmd=resource&f=source.png HTTP/1.1" 200 -
222.109.97.77 - - [13/Oct/2012 18:31:58] "GET /favicon.ico HTTP/1.1" 404 -
222.109.97.77 - - [13/Oct/2012 18:32:44] "GET /twitter_login?__debugger__=yes&cmd=source&frm=46303632&s=Z9BvieZalgvYroC4ILrG HTTP/1.1" 200 -
 * Detected change in 'unome.py', reloading
------- Login -------
----------------------------------------
Exception happened during processing of request from ('222.109.97.77', 63422)
----------------------------------------
------- Login -------
------- Login -------
------- Login -------
------- Login -------
 * Restarting with reloader
222.109.97.77 - - [13/Oct/2012 18:34:27] "GET /twitter_login HTTP/1.1" 302 -
222.109.97.77 - - [13/Oct/2012 18:35:12] "GET /oauth-athorized?oauth_token=DEUFMXa0wbDKvlgMlwgpC2TBKT7XZXxeBH3tKA5v3I&oauth_verifier=30o7hgJE6rTVjFZLIB9Y16XkYAINL0SkCsrIZB9gw HTTP/1.1" 500 -
Traceback (most recent call last):
  File "/usr/local/lib/python2.7/dist-packages/flask/app.py", line 1701, in __call__
    return self.wsgi_app(environ, start_response)
  File "/usr/local/lib/python2.7/dist-packages/flask/app.py", line 1689, in wsgi_app
    response = self.make_response(self.handle_exception(e))
  File "/usr/local/lib/python2.7/dist-packages/flask/app.py", line 1687, in wsgi_app
    response = self.full_dispatch_request()
  File "/usr/local/lib/python2.7/dist-packages/flask/app.py", line 1360, in full_dispatch_request
    rv = self.handle_user_exception(e)
  File "/usr/local/lib/python2.7/dist-packages/flask/app.py", line 1358, in full_dispatch_request
    rv = self.dispatch_request()
  File "/usr/local/lib/python2.7/dist-packages/flask/app.py", line 1344, in dispatch_request
    return self.view_functions[rule.endpoint](**req.view_args)
  File "/usr/local/lib/python2.7/dist-packages/flask_oauth.py", line 433, in decorated
    return f(*((data,) + args), **kwargs)
  File "/home/luman/project/Unome/unome.py", line 48, in oauth_authorized
    flash('You were signed in as %s' % resp['screen_name'])
NameError: global name 'flash' is not defined
222.109.97.77 - - [13/Oct/2012 18:35:12] "GET /oauth-athorized?__debugger__=yes&cmd=resource&f=style.css HTTP/1.1" 200 -
222.109.97.77 - - [13/Oct/2012 18:35:12] "GET /oauth-athorized?__debugger__=yes&cmd=resource&f=jquery.js HTTP/1.1" 200 -
222.109.97.77 - - [13/Oct/2012 18:35:12] "GET /oauth-athorized?__debugger__=yes&cmd=resource&f=debugger.js HTTP/1.1" 200 -
222.109.97.77 - - [13/Oct/2012 18:35:12] "GET /oauth-athorized?__debugger__=yes&cmd=resource&f=ubuntu.ttf HTTP/1.1" 200 -
222.109.97.77 - - [13/Oct/2012 18:35:12] "GET /oauth-athorized?__debugger__=yes&cmd=resource&f=console.png HTTP/1.1" 200 -
222.109.97.77 - - [13/Oct/2012 18:35:12] "GET /oauth-athorized?__debugger__=yes&cmd=resource&f=source.png HTTP/1.1" 200 -
222.109.97.77 - - [13/Oct/2012 18:35:12] "GET /favicon.ico HTTP/1.1" 404 -
 * Detected change in 'unome.py', reloading
------- Login -------
-------OAuth Authorized Phase-------
 * Restarting with reloader
222.109.97.77 - - [13/Oct/2012 18:35:31] "GET /oauth-athorized?oauth_token=DEUFMXa0wbDKvlgMlwgpC2TBKT7XZXxeBH3tKA5v3I&oauth_verifier=30o7hgJE6rTVjFZLIB9Y16XkYAINL0SkCsrIZB9gw HTTP/1.1" 500 -
Traceback (most recent call last):
  File "/usr/local/lib/python2.7/dist-packages/flask/app.py", line 1701, in __call__
    return self.wsgi_app(environ, start_response)
  File "/usr/local/lib/python2.7/dist-packages/flask/app.py", line 1689, in wsgi_app
    response = self.make_response(self.handle_exception(e))
  File "/usr/local/lib/python2.7/dist-packages/flask/app.py", line 1687, in wsgi_app
    response = self.full_dispatch_request()
  File "/usr/local/lib/python2.7/dist-packages/flask/app.py", line 1360, in full_dispatch_request
    rv = self.handle_user_exception(e)
  File "/usr/local/lib/python2.7/dist-packages/flask/app.py", line 1358, in full_dispatch_request
    rv = self.dispatch_request()
  File "/usr/local/lib/python2.7/dist-packages/flask/app.py", line 1344, in dispatch_request
    return self.view_functions[rule.endpoint](**req.view_args)
  File "/usr/local/lib/python2.7/dist-packages/flask_oauth.py", line 427, in decorated
    data = self.handle_oauth1_response()
  File "/usr/local/lib/python2.7/dist-packages/flask_oauth.py", line 379, in handle_oauth1_response
    type='invalid_response', data=data)
OAuthException: Invalid response from twitter
222.109.97.77 - - [13/Oct/2012 18:35:31] "GET /oauth-athorized?__debugger__=yes&cmd=resource&f=style.css HTTP/1.1" 200 -
222.109.97.77 - - [13/Oct/2012 18:35:31] "GET /oauth-athorized?__debugger__=yes&cmd=resource&f=jquery.js HTTP/1.1" 200 -
222.109.97.77 - - [13/Oct/2012 18:35:31] "GET /oauth-athorized?__debugger__=yes&cmd=resource&f=debugger.js HTTP/1.1" 200 -
222.109.97.77 - - [13/Oct/2012 18:35:31] "GET /oauth-athorized?__debugger__=yes&cmd=resource&f=ubuntu.ttf HTTP/1.1" 200 -
222.109.97.77 - - [13/Oct/2012 18:35:31] "GET /oauth-athorized?__debugger__=yes&cmd=resource&f=source.png HTTP/1.1" 200 -
222.109.97.77 - - [13/Oct/2012 18:35:31] "GET /oauth-athorized?__debugger__=yes&cmd=resource&f=console.png HTTP/1.1" 200 -
222.109.97.77 - - [13/Oct/2012 18:35:37] "GET /oauth-athorized?oauth_token=DEUFMXa0wbDKvlgMlwgpC2TBKT7XZXxeBH3tKA5v3I&oauth_verifier=30o7hgJE6rTVjFZLIB9Y16XkYAINL0SkCsrIZB9gw HTTP/1.1" 500 -
Traceback (most recent call last):
  File "/usr/local/lib/python2.7/dist-packages/flask/app.py", line 1701, in __call__
    return self.wsgi_app(environ, start_response)
  File "/usr/local/lib/python2.7/dist-packages/flask/app.py", line 1689, in wsgi_app
    response = self.make_response(self.handle_exception(e))
  File "/usr/local/lib/python2.7/dist-packages/flask/app.py", line 1687, in wsgi_app
    response = self.full_dispatch_request()
  File "/usr/local/lib/python2.7/dist-packages/flask/app.py", line 1360, in full_dispatch_request
    rv = self.handle_user_exception(e)
  File "/usr/local/lib/python2.7/dist-packages/flask/app.py", line 1358, in full_dispatch_request
    rv = self.dispatch_request()
  File "/usr/local/lib/python2.7/dist-packages/flask/app.py", line 1344, in dispatch_request
    return self.view_functions[rule.endpoint](**req.view_args)
  File "/usr/local/lib/python2.7/dist-packages/flask_oauth.py", line 427, in decorated
    data = self.handle_oauth1_response()
  File "/usr/local/lib/python2.7/dist-packages/flask_oauth.py", line 379, in handle_oauth1_response
    type='invalid_response', data=data)
OAuthException: Invalid response from twitter
222.109.97.77 - - [13/Oct/2012 18:35:37] "GET /oauth-athorized?__debugger__=yes&cmd=resource&f=style.css HTTP/1.1" 200 -
222.109.97.77 - - [13/Oct/2012 18:35:37] "GET /oauth-athorized?__debugger__=yes&cmd=resource&f=jquery.js HTTP/1.1" 200 -
222.109.97.77 - - [13/Oct/2012 18:35:37] "GET /oauth-athorized?__debugger__=yes&cmd=resource&f=debugger.js HTTP/1.1" 200 -
222.109.97.77 - - [13/Oct/2012 18:35:37] "GET /oauth-athorized?__debugger__=yes&cmd=resource&f=ubuntu.ttf HTTP/1.1" 200 -
222.109.97.77 - - [13/Oct/2012 18:35:37] "GET /oauth-athorized?__debugger__=yes&cmd=resource&f=console.png HTTP/1.1" 200 -
222.109.97.77 - - [13/Oct/2012 18:35:37] "GET /oauth-athorized?__debugger__=yes&cmd=resource&f=source.png HTTP/1.1" 200 -
222.109.97.77 - - [13/Oct/2012 18:35:39] "GET /oauth-athorized?oauth_token=DEUFMXa0wbDKvlgMlwgpC2TBKT7XZXxeBH3tKA5v3I&oauth_verifier=30o7hgJE6rTVjFZLIB9Y16XkYAINL0SkCsrIZB9gw HTTP/1.1" 500 -
Traceback (most recent call last):
  File "/usr/local/lib/python2.7/dist-packages/flask/app.py", line 1701, in __call__
    return self.wsgi_app(environ, start_response)
  File "/usr/local/lib/python2.7/dist-packages/flask/app.py", line 1689, in wsgi_app
    response = self.make_response(self.handle_exception(e))
  File "/usr/local/lib/python2.7/dist-packages/flask/app.py", line 1687, in wsgi_app
    response = self.full_dispatch_request()
  File "/usr/local/lib/python2.7/dist-packages/flask/app.py", line 1360, in full_dispatch_request
    rv = self.handle_user_exception(e)
  File "/usr/local/lib/python2.7/dist-packages/flask/app.py", line 1358, in full_dispatch_request
    rv = self.dispatch_request()
  File "/usr/local/lib/python2.7/dist-packages/flask/app.py", line 1344, in dispatch_request
    return self.view_functions[rule.endpoint](**req.view_args)
  File "/usr/local/lib/python2.7/dist-packages/flask_oauth.py", line 427, in decorated
    data = self.handle_oauth1_response()
  File "/usr/local/lib/python2.7/dist-packages/flask_oauth.py", line 379, in handle_oauth1_response
    type='invalid_response', data=data)
OAuthException: Invalid response from twitter
222.109.97.77 - - [13/Oct/2012 18:35:39] "GET /oauth-athorized?__debugger__=yes&cmd=resource&f=style.css HTTP/1.1" 200 -
222.109.97.77 - - [13/Oct/2012 18:35:39] "GET /oauth-athorized?__debugger__=yes&cmd=resource&f=debugger.js HTTP/1.1" 200 -
222.109.97.77 - - [13/Oct/2012 18:35:39] "GET /oauth-athorized?__debugger__=yes&cmd=resource&f=jquery.js HTTP/1.1" 200 -
222.109.97.77 - - [13/Oct/2012 18:35:39] "GET /oauth-athorized?__debugger__=yes&cmd=resource&f=ubuntu.ttf HTTP/1.1" 200 -
222.109.97.77 - - [13/Oct/2012 18:35:39] "GET /oauth-athorized?__debugger__=yes&cmd=resource&f=console.png HTTP/1.1" 200 -
222.109.97.77 - - [13/Oct/2012 18:35:39] "GET /oauth-athorized?__debugger__=yes&cmd=resource&f=source.png HTTP/1.1" 200 -
222.109.97.77 - - [13/Oct/2012 18:35:44] "GET /twitter_login HTTP/1.1" 302 -
222.109.97.77 - - [13/Oct/2012 18:35:47] "GET /oauth-athorized?oauth_token=8LzAXkO5FftGNNgFYYhIqJnHWoljBv9AKv6hJ7miUQU&oauth_verifier=DcXole4iNSbh930zRyLwvEQLoaQYv43eUvfjr95bdDs HTTP/1.1" 302 -
222.109.97.77 - - [13/Oct/2012 18:35:48] "GET / HTTP/1.1" 200 -
222.109.97.77 - - [13/Oct/2012 18:35:48] "GET /favicon.ico HTTP/1.1" 404 -
 * Detected change in 'unome.py', reloading
------- Login -------
-------OAuth Authorized Phase-------
 * Restarting with reloader
222.109.97.77 - - [13/Oct/2012 18:38:24] "GET / HTTP/1.1" 200 -
222.109.97.77 - - [13/Oct/2012 18:38:24] "GET /static/css/style.css HTTP/1.1" 200 -
222.109.97.77 - - [13/Oct/2012 18:38:24] "GET /static/css/base.css HTTP/1.1" 200 -
222.109.97.77 - - [13/Oct/2012 18:38:24] "GET /static/css/font-awesome-ie7.css HTTP/1.1" 200 -
222.109.97.77 - - [13/Oct/2012 18:38:24] "GET /static/css/font-awesome.css HTTP/1.1" 200 -
222.109.97.77 - - [13/Oct/2012 18:38:24] "GET /static/font/fontawesome-webfont.woff HTTP/1.1" 200 -
222.109.97.77 - - [13/Oct/2012 18:38:28] "GET /twitter_login HTTP/1.1" 302 -
222.109.97.77 - - [13/Oct/2012 18:38:33] "GET /oauth-athorized?oauth_token=DfFyTE5H1UrpOgGSXZtpv4G6guQYbhGCjSAR8ptr8&oauth_verifier=lA8GfAXpFRY142u7msH92gea4LU6gZdX5LsB4ryug HTTP/1.1" 500 -
Traceback (most recent call last):
  File "/usr/local/lib/python2.7/dist-packages/flask/app.py", line 1701, in __call__
    return self.wsgi_app(environ, start_response)
  File "/usr/local/lib/python2.7/dist-packages/flask/app.py", line 1689, in wsgi_app
    response = self.make_response(self.handle_exception(e))
  File "/usr/local/lib/python2.7/dist-packages/flask/app.py", line 1687, in wsgi_app
    response = self.full_dispatch_request()
  File "/usr/local/lib/python2.7/dist-packages/flask/app.py", line 1360, in full_dispatch_request
    rv = self.handle_user_exception(e)
  File "/usr/local/lib/python2.7/dist-packages/flask/app.py", line 1358, in full_dispatch_request
    rv = self.dispatch_request()
  File "/usr/local/lib/python2.7/dist-packages/flask/app.py", line 1344, in dispatch_request
    return self.view_functions[rule.endpoint](**req.view_args)
  File "/usr/local/lib/python2.7/dist-packages/flask_oauth.py", line 427, in decorated
    data = self.handle_oauth1_response()
  File "/usr/local/lib/python2.7/dist-packages/flask_oauth.py", line 379, in handle_oauth1_response
    type='invalid_response', data=data)
OAuthException: Invalid response from twitter
222.109.97.77 - - [13/Oct/2012 18:38:33] "GET /oauth-athorized?__debugger__=yes&cmd=resource&f=style.css HTTP/1.1" 200 -
222.109.97.77 - - [13/Oct/2012 18:38:33] "GET /oauth-athorized?__debugger__=yes&cmd=resource&f=jquery.js HTTP/1.1" 200 -
222.109.97.77 - - [13/Oct/2012 18:38:33] "GET /oauth-athorized?__debugger__=yes&cmd=resource&f=debugger.js HTTP/1.1" 200 -
222.109.97.77 - - [13/Oct/2012 18:38:34] "GET /oauth-athorized?__debugger__=yes&cmd=resource&f=ubuntu.ttf HTTP/1.1" 200 -
222.109.97.77 - - [13/Oct/2012 18:38:34] "GET /oauth-athorized?__debugger__=yes&cmd=resource&f=source.png HTTP/1.1" 200 -
222.109.97.77 - - [13/Oct/2012 18:38:34] "GET /oauth-athorized?__debugger__=yes&cmd=resource&f=console.png HTTP/1.1" 200 -
222.109.97.77 - - [13/Oct/2012 18:38:34] "GET /favicon.ico HTTP/1.1" 404 -
222.109.97.77 - - [13/Oct/2012 18:38:41] "GET / HTTP/1.1" 200 -
222.109.97.77 - - [13/Oct/2012 18:38:42] "GET /favicon.ico HTTP/1.1" 404 -
222.109.97.77 - - [13/Oct/2012 18:38:43] "GET / HTTP/1.1" 200 -
222.109.97.77 - - [13/Oct/2012 18:38:43] "GET /static/css/style.css HTTP/1.1" 304 -
222.109.97.77 - - [13/Oct/2012 18:38:43] "GET /static/css/base.css HTTP/1.1" 304 -
222.109.97.77 - - [13/Oct/2012 18:38:43] "GET /static/css/font-awesome-ie7.css HTTP/1.1" 304 -
222.109.97.77 - - [13/Oct/2012 18:38:43] "GET /static/css/font-awesome.css HTTP/1.1" 304 -
222.109.97.77 - - [13/Oct/2012 18:38:43] "GET /static/font/fontawesome-webfont.woff HTTP/1.1" 304 -
222.109.97.77 - - [13/Oct/2012 18:38:43] "GET /favicon.ico HTTP/1.1" 404 -
222.109.97.77 - - [13/Oct/2012 18:38:46] "GET /twitter_login HTTP/1.1" 302 -
222.109.97.77 - - [13/Oct/2012 18:38:49] "GET /oauth-athorized?oauth_token=dG9kYwRCcVqAeMQpCebkEZInZJ7obcXxb6tl7I1snc&oauth_verifier=Nzoz5brK5N1p84MA2OIlVUlw2aHgJPRbfamOOVMv8PU HTTP/1.1" 500 -
Traceback (most recent call last):
  File "/usr/local/lib/python2.7/dist-packages/flask/app.py", line 1701, in __call__
    return self.wsgi_app(environ, start_response)
  File "/usr/local/lib/python2.7/dist-packages/flask/app.py", line 1689, in wsgi_app
    response = self.make_response(self.handle_exception(e))
  File "/usr/local/lib/python2.7/dist-packages/flask/app.py", line 1687, in wsgi_app
    response = self.full_dispatch_request()
  File "/usr/local/lib/python2.7/dist-packages/flask/app.py", line 1360, in full_dispatch_request
    rv = self.handle_user_exception(e)
  File "/usr/local/lib/python2.7/dist-packages/flask/app.py", line 1358, in full_dispatch_request
    rv = self.dispatch_request()
  File "/usr/local/lib/python2.7/dist-packages/flask/app.py", line 1344, in dispatch_request
    return self.view_functions[rule.endpoint](**req.view_args)
  File "/usr/local/lib/python2.7/dist-packages/flask_oauth.py", line 427, in decorated
    data = self.handle_oauth1_response()
  File "/usr/local/lib/python2.7/dist-packages/flask_oauth.py", line 379, in handle_oauth1_response
    type='invalid_response', data=data)
OAuthException: Invalid response from twitter
222.109.97.77 - - [13/Oct/2012 18:38:49] "GET /oauth-athorized?__debugger__=yes&cmd=resource&f=style.css HTTP/1.1" 200 -
222.109.97.77 - - [13/Oct/2012 18:38:49] "GET /oauth-athorized?__debugger__=yes&cmd=resource&f=jquery.js HTTP/1.1" 200 -
222.109.97.77 - - [13/Oct/2012 18:38:49] "GET /oauth-athorized?__debugger__=yes&cmd=resource&f=debugger.js HTTP/1.1" 200 -
222.109.97.77 - - [13/Oct/2012 18:38:49] "GET /oauth-athorized?__debugger__=yes&cmd=resource&f=ubuntu.ttf HTTP/1.1" 200 -
222.109.97.77 - - [13/Oct/2012 18:38:50] "GET /oauth-athorized?__debugger__=yes&cmd=resource&f=console.png HTTP/1.1" 200 -
222.109.97.77 - - [13/Oct/2012 18:38:50] "GET /oauth-athorized?__debugger__=yes&cmd=resource&f=source.png HTTP/1.1" 200 -
222.109.97.77 - - [13/Oct/2012 18:38:50] "GET /favicon.ico HTTP/1.1" 404 -
222.109.97.77 - - [13/Oct/2012 18:40:08] "GET /oauth-athorized?oauth_token=dG9kYwRCcVqAeMQpCebkEZInZJ7obcXxb6tl7I1snc&oauth_verifier=Nzoz5brK5N1p84MA2OIlVUlw2aHgJPRbfamOOVMv8PU HTTP/1.1" 500 -
Traceback (most recent call last):
  File "/usr/local/lib/python2.7/dist-packages/flask/app.py", line 1701, in __call__
    return self.wsgi_app(environ, start_response)
  File "/usr/local/lib/python2.7/dist-packages/flask/app.py", line 1689, in wsgi_app
    response = self.make_response(self.handle_exception(e))
  File "/usr/local/lib/python2.7/dist-packages/flask/app.py", line 1687, in wsgi_app
    response = self.full_dispatch_request()
  File "/usr/local/lib/python2.7/dist-packages/flask/app.py", line 1360, in full_dispatch_request
    rv = self.handle_user_exception(e)
  File "/usr/local/lib/python2.7/dist-packages/flask/app.py", line 1358, in full_dispatch_request
    rv = self.dispatch_request()
  File "/usr/local/lib/python2.7/dist-packages/flask/app.py", line 1344, in dispatch_request
    return self.view_functions[rule.endpoint](**req.view_args)
  File "/usr/local/lib/python2.7/dist-packages/flask_oauth.py", line 427, in decorated
    data = self.handle_oauth1_response()
  File "/usr/local/lib/python2.7/dist-packages/flask_oauth.py", line 379, in handle_oauth1_response
    type='invalid_response', data=data)
OAuthException: Invalid response from twitter
222.109.97.77 - - [13/Oct/2012 18:40:09] "GET /oauth-athorized?__debugger__=yes&cmd=resource&f=style.css HTTP/1.1" 200 -
222.109.97.77 - - [13/Oct/2012 18:40:09] "GET /oauth-athorized?__debugger__=yes&cmd=resource&f=jquery.js HTTP/1.1" 200 -
222.109.97.77 - - [13/Oct/2012 18:40:09] "GET /oauth-athorized?__debugger__=yes&cmd=resource&f=debugger.js HTTP/1.1" 200 -
222.109.97.77 - - [13/Oct/2012 18:40:09] "GET /oauth-athorized?__debugger__=yes&cmd=resource&f=ubuntu.ttf HTTP/1.1" 200 -
222.109.97.77 - - [13/Oct/2012 18:40:09] "GET /oauth-athorized?__debugger__=yes&cmd=resource&f=console.png HTTP/1.1" 200 -
222.109.97.77 - - [13/Oct/2012 18:40:09] "GET /oauth-athorized?__debugger__=yes&cmd=resource&f=source.png HTTP/1.1" 200 -
222.109.97.77 - - [13/Oct/2012 18:40:09] "GET /favicon.ico HTTP/1.1" 404 -
222.109.97.77 - - [13/Oct/2012 18:40:11] "GET /oauth-athorized?__debugger__=yes&cmd=source&frm=37989136&s=yN0cXICaRatmQnSTiIQL HTTP/1.1" 200 -
222.109.97.77 - - [13/Oct/2012 18:40:17] "GET /oauth-athorized?__debugger__=yes&cmd=content&frm=37403984&s=yN0cXICaRatmQnSTiIQL HTTP/1.1" 200 -
222.109.97.77 - - [13/Oct/2012 18:40:19] "GET /oauth-athorized?__debugger__=yes&cmd=&frm=37403984&s=yN0cXICaRatmQnSTiIQL HTTP/1.1" 200 -
222.109.97.77 - - [13/Oct/2012 18:40:19] "GET /oauth-athorized?__debugger__=yes&cmd=fuck&frm=37403984&s=yN0cXICaRatmQnSTiIQL HTTP/1.1" 200 -
222.109.97.77 - - [13/Oct/2012 18:40:20] "GET /oauth-athorized?__debugger__=yes&cmd=&frm=37403984&s=yN0cXICaRatmQnSTiIQL HTTP/1.1" 200 -
222.109.97.77 - - [13/Oct/2012 18:40:21] "GET /oauth-athorized?__debugger__=yes&cmd=print+fuck&frm=37403984&s=yN0cXICaRatmQnSTiIQL HTTP/1.1" 200 -
222.109.97.77 - - [13/Oct/2012 18:40:24] "GET /oauth-athorized?__debugger__=yes&cmd=print+'fuck'&frm=37403984&s=yN0cXICaRatmQnSTiIQL HTTP/1.1" 200 -
222.109.97.77 - - [13/Oct/2012 18:40:41] "GET /oauth-athorized?oauth_token=dG9kYwRCcVqAeMQpCebkEZInZJ7obcXxb6tl7I1snc&oauth_verifier=Nzoz5brK5N1p84MA2OIlVUlw2aHgJPRbfamOOVMv8PU HTTP/1.1" 500 -
Traceback (most recent call last):
  File "/usr/local/lib/python2.7/dist-packages/flask/app.py", line 1701, in __call__
    return self.wsgi_app(environ, start_response)
  File "/usr/local/lib/python2.7/dist-packages/flask/app.py", line 1689, in wsgi_app
    response = self.make_response(self.handle_exception(e))
  File "/usr/local/lib/python2.7/dist-packages/flask/app.py", line 1687, in wsgi_app
    response = self.full_dispatch_request()
  File "/usr/local/lib/python2.7/dist-packages/flask/app.py", line 1360, in full_dispatch_request
    rv = self.handle_user_exception(e)
  File "/usr/local/lib/python2.7/dist-packages/flask/app.py", line 1358, in full_dispatch_request
    rv = self.dispatch_request()
  File "/usr/local/lib/python2.7/dist-packages/flask/app.py", line 1344, in dispatch_request
    return self.view_functions[rule.endpoint](**req.view_args)
  File "/usr/local/lib/python2.7/dist-packages/flask_oauth.py", line 427, in decorated
    data = self.handle_oauth1_response()
  File "/usr/local/lib/python2.7/dist-packages/flask_oauth.py", line 379, in handle_oauth1_response
    type='invalid_response', data=data)
OAuthException: Invalid response from twitter
222.109.97.77 - - [13/Oct/2012 18:40:41] "GET /oauth-athorized?__debugger__=yes&cmd=resource&f=style.css HTTP/1.1" 200 -
222.109.97.77 - - [13/Oct/2012 18:40:41] "GET /oauth-athorized?__debugger__=yes&cmd=resource&f=jquery.js HTTP/1.1" 200 -
222.109.97.77 - - [13/Oct/2012 18:40:41] "GET /oauth-athorized?__debugger__=yes&cmd=resource&f=debugger.js HTTP/1.1" 200 -
222.109.97.77 - - [13/Oct/2012 18:40:41] "GET /oauth-athorized?__debugger__=yes&cmd=resource&f=ubuntu.ttf HTTP/1.1" 200 -
222.109.97.77 - - [13/Oct/2012 18:40:41] "GET /oauth-athorized?__debugger__=yes&cmd=resource&f=console.png HTTP/1.1" 200 -
222.109.97.77 - - [13/Oct/2012 18:40:41] "GET /oauth-athorized?__debugger__=yes&cmd=resource&f=source.png HTTP/1.1" 200 -
222.109.97.77 - - [13/Oct/2012 18:40:58] "GET / HTTP/1.1" 200 -
222.109.97.77 - - [13/Oct/2012 18:40:58] "GET /favicon.ico HTTP/1.1" 404 -
222.109.97.77 - - [13/Oct/2012 18:41:09] "GET /twitter_login HTTP/1.1" 302 -
222.109.97.77 - - [13/Oct/2012 18:41:13] "GET /oauth-athorized?oauth_token=RIFJ23RipapGk3Vg3FR6B9pPlSSfQaXupkbkx77k&oauth_verifier=uiUeOuLZnZsgwkuE4pXdtcd9hsl0bQEh8GVDNW05PA HTTP/1.1" 500 -
Traceback (most recent call last):
  File "/usr/local/lib/python2.7/dist-packages/flask/app.py", line 1701, in __call__
    return self.wsgi_app(environ, start_response)
  File "/usr/local/lib/python2.7/dist-packages/flask/app.py", line 1689, in wsgi_app
    response = self.make_response(self.handle_exception(e))
  File "/usr/local/lib/python2.7/dist-packages/flask/app.py", line 1687, in wsgi_app
    response = self.full_dispatch_request()
  File "/usr/local/lib/python2.7/dist-packages/flask/app.py", line 1360, in full_dispatch_request
    rv = self.handle_user_exception(e)
  File "/usr/local/lib/python2.7/dist-packages/flask/app.py", line 1358, in full_dispatch_request
    rv = self.dispatch_request()
  File "/usr/local/lib/python2.7/dist-packages/flask/app.py", line 1344, in dispatch_request
    return self.view_functions[rule.endpoint](**req.view_args)
  File "/usr/local/lib/python2.7/dist-packages/flask_oauth.py", line 427, in decorated
    data = self.handle_oauth1_response()
  File "/usr/local/lib/python2.7/dist-packages/flask_oauth.py", line 379, in handle_oauth1_response
    type='invalid_response', data=data)
OAuthException: Invalid response from twitter
222.109.97.77 - - [13/Oct/2012 18:41:13] "GET /oauth-athorized?__debugger__=yes&cmd=resource&f=style.css HTTP/1.1" 200 -
222.109.97.77 - - [13/Oct/2012 18:41:13] "GET /oauth-athorized?__debugger__=yes&cmd=resource&f=debugger.js HTTP/1.1" 200 -
222.109.97.77 - - [13/Oct/2012 18:41:13] "GET /oauth-athorized?__debugger__=yes&cmd=resource&f=jquery.js HTTP/1.1" 200 -
222.109.97.77 - - [13/Oct/2012 18:41:13] "GET /oauth-athorized?__debugger__=yes&cmd=resource&f=ubuntu.ttf HTTP/1.1" 200 -
222.109.97.77 - - [13/Oct/2012 18:41:13] "GET /oauth-athorized?__debugger__=yes&cmd=resource&f=console.png HTTP/1.1" 200 -
222.109.97.77 - - [13/Oct/2012 18:41:13] "GET /oauth-athorized?__debugger__=yes&cmd=resource&f=source.png HTTP/1.1" 200 -
222.109.97.77 - - [13/Oct/2012 18:41:13] "GET /favicon.ico HTTP/1.1" 404 -
 * Detected change in 'unome.py', reloading
------- Login -------
------- Login -------
------- Login -------
 * Restarting with reloader
222.109.97.77 - - [13/Oct/2012 18:41:59] "GET /oauth-athorized?oauth_token=RIFJ23RipapGk3Vg3FR6B9pPlSSfQaXupkbkx77k&oauth_verifier=uiUeOuLZnZsgwkuE4pXdtcd9hsl0bQEh8GVDNW05PA HTTP/1.1" 500 -
Traceback (most recent call last):
  File "/usr/local/lib/python2.7/dist-packages/flask/app.py", line 1701, in __call__
    return self.wsgi_app(environ, start_response)
  File "/usr/local/lib/python2.7/dist-packages/flask/app.py", line 1689, in wsgi_app
    response = self.make_response(self.handle_exception(e))
  File "/usr/local/lib/python2.7/dist-packages/flask/app.py", line 1687, in wsgi_app
    response = self.full_dispatch_request()
  File "/usr/local/lib/python2.7/dist-packages/flask/app.py", line 1360, in full_dispatch_request
    rv = self.handle_user_exception(e)
  File "/usr/local/lib/python2.7/dist-packages/flask/app.py", line 1358, in full_dispatch_request
    rv = self.dispatch_request()
  File "/usr/local/lib/python2.7/dist-packages/flask/app.py", line 1344, in dispatch_request
    return self.view_functions[rule.endpoint](**req.view_args)
  File "/usr/local/lib/python2.7/dist-packages/flask_oauth.py", line 427, in decorated
    data = self.handle_oauth1_response()
  File "/usr/local/lib/python2.7/dist-packages/flask_oauth.py", line 379, in handle_oauth1_response
    type='invalid_response', data=data)
OAuthException: Invalid response from twitter
222.109.97.77 - - [13/Oct/2012 18:41:59] "GET /oauth-athorized?__debugger__=yes&cmd=resource&f=style.css HTTP/1.1" 200 -
222.109.97.77 - - [13/Oct/2012 18:41:59] "GET /oauth-athorized?__debugger__=yes&cmd=resource&f=jquery.js HTTP/1.1" 200 -
222.109.97.77 - - [13/Oct/2012 18:41:59] "GET /oauth-athorized?__debugger__=yes&cmd=resource&f=debugger.js HTTP/1.1" 200 -
222.109.97.77 - - [13/Oct/2012 18:41:59] "GET /oauth-athorized?__debugger__=yes&cmd=resource&f=ubuntu.ttf HTTP/1.1" 200 -
222.109.97.77 - - [13/Oct/2012 18:42:00] "GET /oauth-athorized?__debugger__=yes&cmd=resource&f=console.png HTTP/1.1" 200 -
222.109.97.77 - - [13/Oct/2012 18:42:00] "GET /oauth-athorized?__debugger__=yes&cmd=resource&f=source.png HTTP/1.1" 200 -
222.109.97.77 - - [13/Oct/2012 18:42:02] "GET / HTTP/1.1" 200 -
222.109.97.77 - - [13/Oct/2012 18:42:02] "GET /favicon.ico HTTP/1.1" 404 -
222.109.97.77 - - [13/Oct/2012 18:42:05] "GET /twitter_login HTTP/1.1" 302 -
222.109.97.77 - - [13/Oct/2012 18:42:09] "GET /oauth-athorized?oauth_token=QXUh0uXnhX0Y3ZRy3Xw721f53PVBqw5tLwIBdxeBw0E&oauth_verifier=X1bpFbEialbv8tAzizy0NP4r5Zc99kZOZkxZLMstc HTTP/1.1" 500 -
Traceback (most recent call last):
  File "/usr/local/lib/python2.7/dist-packages/flask/app.py", line 1701, in __call__
    return self.wsgi_app(environ, start_response)
  File "/usr/local/lib/python2.7/dist-packages/flask/app.py", line 1689, in wsgi_app
    response = self.make_response(self.handle_exception(e))
  File "/usr/local/lib/python2.7/dist-packages/flask/app.py", line 1687, in wsgi_app
    response = self.full_dispatch_request()
  File "/usr/local/lib/python2.7/dist-packages/flask/app.py", line 1360, in full_dispatch_request
    rv = self.handle_user_exception(e)
  File "/usr/local/lib/python2.7/dist-packages/flask/app.py", line 1358, in full_dispatch_request
    rv = self.dispatch_request()
  File "/usr/local/lib/python2.7/dist-packages/flask/app.py", line 1344, in dispatch_request
    return self.view_functions[rule.endpoint](**req.view_args)
  File "/usr/local/lib/python2.7/dist-packages/flask_oauth.py", line 427, in decorated
    data = self.handle_oauth1_response()
  File "/usr/local/lib/python2.7/dist-packages/flask_oauth.py", line 379, in handle_oauth1_response
    type='invalid_response', data=data)
OAuthException: Invalid response from twitter
222.109.97.77 - - [13/Oct/2012 18:42:09] "GET /oauth-athorized?__debugger__=yes&cmd=resource&f=style.css HTTP/1.1" 200 -
222.109.97.77 - - [13/Oct/2012 18:42:09] "GET /oauth-athorized?__debugger__=yes&cmd=resource&f=jquery.js HTTP/1.1" 200 -
222.109.97.77 - - [13/Oct/2012 18:42:09] "GET /oauth-athorized?__debugger__=yes&cmd=resource&f=debugger.js HTTP/1.1" 200 -
222.109.97.77 - - [13/Oct/2012 18:42:09] "GET /oauth-athorized?__debugger__=yes&cmd=resource&f=ubuntu.ttf HTTP/1.1" 200 -
222.109.97.77 - - [13/Oct/2012 18:42:09] "GET /oauth-athorized?__debugger__=yes&cmd=resource&f=console.png HTTP/1.1" 200 -
222.109.97.77 - - [13/Oct/2012 18:42:09] "GET /oauth-athorized?__debugger__=yes&cmd=resource&f=source.png HTTP/1.1" 200 -
222.109.97.77 - - [13/Oct/2012 18:42:10] "GET /favicon.ico HTTP/1.1" 404 -
222.109.97.77 - - [13/Oct/2012 18:42:13] "GET /favicon.ico HTTP/1.1" 404 -
222.109.97.77 - - [13/Oct/2012 18:42:20] "GET /oauth-athorized?denied=QXUh0uXnhX0Y3ZRy3Xw721f53PVBqw5tLwIBdxeBw0E HTTP/1.1" 302 -
222.109.97.77 - - [13/Oct/2012 18:42:20] "GET / HTTP/1.1" 200 -
222.109.97.77 - - [13/Oct/2012 18:42:20] "GET /favicon.ico HTTP/1.1" 404 -
222.109.97.77 - - [13/Oct/2012 18:42:42] "GET / HTTP/1.1" 200 -
222.109.97.77 - - [13/Oct/2012 18:42:42] "GET /static/css/style.css HTTP/1.1" 304 -
222.109.97.77 - - [13/Oct/2012 18:42:42] "GET /static/css/base.css HTTP/1.1" 304 -
222.109.97.77 - - [13/Oct/2012 18:42:42] "GET /static/css/font-awesome-ie7.css HTTP/1.1" 304 -
222.109.97.77 - - [13/Oct/2012 18:42:42] "GET /static/css/font-awesome.css HTTP/1.1" 304 -
222.109.97.77 - - [13/Oct/2012 18:42:42] "GET /static/font/fontawesome-webfont.woff HTTP/1.1" 304 -
222.109.97.77 - - [13/Oct/2012 18:42:42] "GET /favicon.ico HTTP/1.1" 404 -
 * Detected change in 'unome.py', reloading
------- Login -------
-------OAuth Authorized Phase-------
 * Restarting with reloader
222.109.97.77 - - [13/Oct/2012 18:42:52] "GET /twitter_login HTTP/1.1" 302 -
222.109.97.77 - - [13/Oct/2012 18:42:57] "GET /oauth-athorized?oauth_token=wl7wVZ6iufdqUXrJNePQP1VZ6XzjHySmTbUud9wfu0&oauth_verifier=zNWi9PVjlp0uPPgw1kRWEbLF2Q3BhuTWKeEcUygp2kA HTTP/1.1" 500 -
Traceback (most recent call last):
  File "/usr/local/lib/python2.7/dist-packages/flask/app.py", line 1701, in __call__
    return self.wsgi_app(environ, start_response)
  File "/usr/local/lib/python2.7/dist-packages/flask/app.py", line 1689, in wsgi_app
    response = self.make_response(self.handle_exception(e))
  File "/usr/local/lib/python2.7/dist-packages/flask/app.py", line 1687, in wsgi_app
    response = self.full_dispatch_request()
  File "/usr/local/lib/python2.7/dist-packages/flask/app.py", line 1360, in full_dispatch_request
    rv = self.handle_user_exception(e)
  File "/usr/local/lib/python2.7/dist-packages/flask/app.py", line 1358, in full_dispatch_request
    rv = self.dispatch_request()
  File "/usr/local/lib/python2.7/dist-packages/flask/app.py", line 1344, in dispatch_request
    return self.view_functions[rule.endpoint](**req.view_args)
  File "/usr/local/lib/python2.7/dist-packages/flask_oauth.py", line 427, in decorated
    data = self.handle_oauth1_response()
  File "/usr/local/lib/python2.7/dist-packages/flask_oauth.py", line 379, in handle_oauth1_response
    type='invalid_response', data=data)
OAuthException: Invalid response from twitter
222.109.97.77 - - [13/Oct/2012 18:42:57] "GET /oauth-athorized?__debugger__=yes&cmd=resource&f=style.css HTTP/1.1" 200 -
222.109.97.77 - - [13/Oct/2012 18:42:57] "GET /oauth-athorized?__debugger__=yes&cmd=resource&f=jquery.js HTTP/1.1" 200 -
222.109.97.77 - - [13/Oct/2012 18:42:57] "GET /oauth-athorized?__debugger__=yes&cmd=resource&f=debugger.js HTTP/1.1" 200 -
222.109.97.77 - - [13/Oct/2012 18:42:57] "GET /oauth-athorized?__debugger__=yes&cmd=resource&f=ubuntu.ttf HTTP/1.1" 200 -
222.109.97.77 - - [13/Oct/2012 18:42:57] "GET /oauth-athorized?__debugger__=yes&cmd=resource&f=console.png HTTP/1.1" 200 -
222.109.97.77 - - [13/Oct/2012 18:42:57] "GET /oauth-athorized?__debugger__=yes&cmd=resource&f=source.png HTTP/1.1" 200 -
222.109.97.77 - - [13/Oct/2012 18:42:57] "GET /favicon.ico HTTP/1.1" 404 -
222.109.97.77 - - [13/Oct/2012 18:43:20] "GET /oauth-athorized?oauth_token=wl7wVZ6iufdqUXrJNePQP1VZ6XzjHySmTbUud9wfu0&oauth_verifier=zNWi9PVjlp0uPPgw1kRWEbLF2Q3BhuTWKeEcUygp2kA HTTP/1.1" 500 -
Traceback (most recent call last):
  File "/usr/local/lib/python2.7/dist-packages/flask/app.py", line 1701, in __call__
    return self.wsgi_app(environ, start_response)
  File "/usr/local/lib/python2.7/dist-packages/flask/app.py", line 1689, in wsgi_app
    response = self.make_response(self.handle_exception(e))
  File "/usr/local/lib/python2.7/dist-packages/flask/app.py", line 1687, in wsgi_app
    response = self.full_dispatch_request()
  File "/usr/local/lib/python2.7/dist-packages/flask/app.py", line 1360, in full_dispatch_request
    rv = self.handle_user_exception(e)
  File "/usr/local/lib/python2.7/dist-packages/flask/app.py", line 1358, in full_dispatch_request
    rv = self.dispatch_request()
  File "/usr/local/lib/python2.7/dist-packages/flask/app.py", line 1344, in dispatch_request
    return self.view_functions[rule.endpoint](**req.view_args)
  File "/usr/local/lib/python2.7/dist-packages/flask_oauth.py", line 427, in decorated
    data = self.handle_oauth1_response()
  File "/usr/local/lib/python2.7/dist-packages/flask_oauth.py", line 379, in handle_oauth1_response
    type='invalid_response', data=data)
OAuthException: Invalid response from twitter
222.109.97.77 - - [13/Oct/2012 18:43:20] "GET /oauth-athorized?__debugger__=yes&cmd=resource&f=style.css HTTP/1.1" 200 -
222.109.97.77 - - [13/Oct/2012 18:43:20] "GET /oauth-athorized?__debugger__=yes&cmd=resource&f=jquery.js HTTP/1.1" 200 -
222.109.97.77 - - [13/Oct/2012 18:43:20] "GET /oauth-athorized?__debugger__=yes&cmd=resource&f=debugger.js HTTP/1.1" 200 -
222.109.97.77 - - [13/Oct/2012 18:43:20] "GET /oauth-athorized?__debugger__=yes&cmd=resource&f=ubuntu.ttf HTTP/1.1" 200 -
222.109.97.77 - - [13/Oct/2012 18:43:20] "GET /oauth-athorized?__debugger__=yes&cmd=resource&f=console.png HTTP/1.1" 200 -
222.109.97.77 - - [13/Oct/2012 18:43:20] "GET /oauth-athorized?__debugger__=yes&cmd=resource&f=source.png HTTP/1.1" 200 -
222.109.97.77 - - [13/Oct/2012 18:44:04] "GET / HTTP/1.1" 200 -
222.109.97.77 - - [13/Oct/2012 18:44:05] "GET /favicon.ico HTTP/1.1" 404 -
222.109.97.77 - - [13/Oct/2012 18:44:08] "GET /twitter_login HTTP/1.1" 302 -
222.109.97.77 - - [13/Oct/2012 18:44:14] "GET /oauth-athorized?oauth_token=0m2uaGPXt9SVhTSdgzQIaVM42cuGGiKbBZkrgDU&oauth_verifier=8NucjTDhxUfXqvXm0OqGZCb18ELCBtfvFyyE4dE HTTP/1.1" 500 -
Traceback (most recent call last):
  File "/usr/local/lib/python2.7/dist-packages/flask/app.py", line 1701, in __call__
    return self.wsgi_app(environ, start_response)
  File "/usr/local/lib/python2.7/dist-packages/flask/app.py", line 1689, in wsgi_app
    response = self.make_response(self.handle_exception(e))
  File "/usr/local/lib/python2.7/dist-packages/flask/app.py", line 1687, in wsgi_app
    response = self.full_dispatch_request()
  File "/usr/local/lib/python2.7/dist-packages/flask/app.py", line 1360, in full_dispatch_request
    rv = self.handle_user_exception(e)
  File "/usr/local/lib/python2.7/dist-packages/flask/app.py", line 1358, in full_dispatch_request
    rv = self.dispatch_request()
  File "/usr/local/lib/python2.7/dist-packages/flask/app.py", line 1344, in dispatch_request
    return self.view_functions[rule.endpoint](**req.view_args)
  File "/usr/local/lib/python2.7/dist-packages/flask_oauth.py", line 427, in decorated
    data = self.handle_oauth1_response()
  File "/usr/local/lib/python2.7/dist-packages/flask_oauth.py", line 379, in handle_oauth1_response
    type='invalid_response', data=data)
OAuthException: Invalid response from twitter
222.109.97.77 - - [13/Oct/2012 18:44:14] "GET /oauth-athorized?__debugger__=yes&cmd=resource&f=style.css HTTP/1.1" 200 -
222.109.97.77 - - [13/Oct/2012 18:44:14] "GET /oauth-athorized?__debugger__=yes&cmd=resource&f=jquery.js HTTP/1.1" 200 -
222.109.97.77 - - [13/Oct/2012 18:44:14] "GET /oauth-athorized?__debugger__=yes&cmd=resource&f=debugger.js HTTP/1.1" 200 -
222.109.97.77 - - [13/Oct/2012 18:44:14] "GET /oauth-athorized?__debugger__=yes&cmd=resource&f=ubuntu.ttf HTTP/1.1" 200 -
222.109.97.77 - - [13/Oct/2012 18:44:14] "GET /oauth-athorized?__debugger__=yes&cmd=resource&f=source.png HTTP/1.1" 200 -
222.109.97.77 - - [13/Oct/2012 18:44:14] "GET /oauth-athorized?__debugger__=yes&cmd=resource&f=console.png HTTP/1.1" 200 -
222.109.97.77 - - [13/Oct/2012 18:44:14] "GET /favicon.ico HTTP/1.1" 404 -
222.109.97.77 - - [13/Oct/2012 18:44:40] "GET /oauth-athorized?oauth_token=0m2uaGPXt9SVhTSdgzQIaVM42cuGGiKbBZkrgDU&oauth_verifier=8NucjTDhxUfXqvXm0OqGZCb18ELCBtfvFyyE4dE HTTP/1.1" 500 -
Traceback (most recent call last):
  File "/usr/local/lib/python2.7/dist-packages/flask/app.py", line 1701, in __call__
    return self.wsgi_app(environ, start_response)
  File "/usr/local/lib/python2.7/dist-packages/flask/app.py", line 1689, in wsgi_app
    response = self.make_response(self.handle_exception(e))
  File "/usr/local/lib/python2.7/dist-packages/flask/app.py", line 1687, in wsgi_app
    response = self.full_dispatch_request()
  File "/usr/local/lib/python2.7/dist-packages/flask/app.py", line 1360, in full_dispatch_request
    rv = self.handle_user_exception(e)
  File "/usr/local/lib/python2.7/dist-packages/flask/app.py", line 1358, in full_dispatch_request
    rv = self.dispatch_request()
  File "/usr/local/lib/python2.7/dist-packages/flask/app.py", line 1344, in dispatch_request
    return self.view_functions[rule.endpoint](**req.view_args)
  File "/usr/local/lib/python2.7/dist-packages/flask_oauth.py", line 427, in decorated
    data = self.handle_oauth1_response()
  File "/usr/local/lib/python2.7/dist-packages/flask_oauth.py", line 379, in handle_oauth1_response
    type='invalid_response', data=data)
OAuthException: Invalid response from twitter
222.109.97.77 - - [13/Oct/2012 18:44:41] "GET /oauth-athorized?__debugger__=yes&cmd=resource&f=style.css HTTP/1.1" 200 -
222.109.97.77 - - [13/Oct/2012 18:44:41] "GET /oauth-athorized?__debugger__=yes&cmd=resource&f=jquery.js HTTP/1.1" 200 -
222.109.97.77 - - [13/Oct/2012 18:44:41] "GET /oauth-athorized?__debugger__=yes&cmd=resource&f=debugger.js HTTP/1.1" 200 -
222.109.97.77 - - [13/Oct/2012 18:44:41] "GET /oauth-athorized?__debugger__=yes&cmd=resource&f=ubuntu.ttf HTTP/1.1" 200 -
222.109.97.77 - - [13/Oct/2012 18:44:41] "GET /oauth-athorized?__debugger__=yes&cmd=resource&f=console.png HTTP/1.1" 200 -
222.109.97.77 - - [13/Oct/2012 18:44:41] "GET /oauth-athorized?__debugger__=yes&cmd=resource&f=source.png HTTP/1.1" 200 -
222.109.97.77 - - [13/Oct/2012 18:44:41] "GET /favicon.ico HTTP/1.1" 404 -
222.109.97.77 - - [13/Oct/2012 18:45:10] "GET /oauth-athorized?oauth_token=0m2uaGPXt9SVhTSdgzQIaVM42cuGGiKbBZkrgDU&oauth_verifier=8NucjTDhxUfXqvXm0OqGZCb18ELCBtfvFyyE4dE HTTP/1.1" 500 -
Traceback (most recent call last):
  File "/usr/local/lib/python2.7/dist-packages/flask/app.py", line 1701, in __call__
    return self.wsgi_app(environ, start_response)
  File "/usr/local/lib/python2.7/dist-packages/flask/app.py", line 1689, in wsgi_app
    response = self.make_response(self.handle_exception(e))
  File "/usr/local/lib/python2.7/dist-packages/flask/app.py", line 1687, in wsgi_app
    response = self.full_dispatch_request()
  File "/usr/local/lib/python2.7/dist-packages/flask/app.py", line 1360, in full_dispatch_request
    rv = self.handle_user_exception(e)
  File "/usr/local/lib/python2.7/dist-packages/flask/app.py", line 1358, in full_dispatch_request
    rv = self.dispatch_request()
  File "/usr/local/lib/python2.7/dist-packages/flask/app.py", line 1344, in dispatch_request
    return self.view_functions[rule.endpoint](**req.view_args)
  File "/usr/local/lib/python2.7/dist-packages/flask_oauth.py", line 427, in decorated
    data = self.handle_oauth1_response()
  File "/usr/local/lib/python2.7/dist-packages/flask_oauth.py", line 379, in handle_oauth1_response
    type='invalid_response', data=data)
OAuthException: Invalid response from twitter
222.109.97.77 - - [13/Oct/2012 18:45:10] "GET /oauth-athorized?__debugger__=yes&cmd=resource&f=style.css HTTP/1.1" 200 -
222.109.97.77 - - [13/Oct/2012 18:45:10] "GET /oauth-athorized?__debugger__=yes&cmd=resource&f=jquery.js HTTP/1.1" 200 -
222.109.97.77 - - [13/Oct/2012 18:45:10] "GET /oauth-athorized?__debugger__=yes&cmd=resource&f=debugger.js HTTP/1.1" 200 -
222.109.97.77 - - [13/Oct/2012 18:45:10] "GET /oauth-athorized?__debugger__=yes&cmd=resource&f=ubuntu.ttf HTTP/1.1" 200 -
222.109.97.77 - - [13/Oct/2012 18:45:10] "GET /oauth-athorized?__debugger__=yes&cmd=resource&f=console.png HTTP/1.1" 200 -
222.109.97.77 - - [13/Oct/2012 18:45:10] "GET /oauth-athorized?__debugger__=yes&cmd=resource&f=source.png HTTP/1.1" 200 -
222.109.97.77 - - [13/Oct/2012 18:45:11] "GET /favicon.ico HTTP/1.1" 404 -
 * Detected change in 'unome.py', reloading
------- Login -------
------- Login -------
 * Restarting with reloader
